<?xml version="1.0"?>
<robot xmlns:xacro="http://www.ros.org/wiki/xacro" name="ult_robot">

  <link name="base_footprint"/>

  <link name="base_link">
    <visual>
      <geometry>
        <box size="1.0 0.8 0.1"/>
      </geometry>
      <material name="LightGrey">
        <color rgba="0.7 0.7 0.7 1.0"/>
      </material>
    </visual>
    <collision>
      <geometry>
        <box size="1.0 0.8 0.1"/>
      </geometry>
    </collision>
    <inertial>
      <mass value="2.0"/>
      <origin xyz="0.0 0.0 -0.05" rpy="0.0 0.0 0.0"/>
      <inertia ixx="0.1667" ixy="0.0" ixz="0.0" iyy="0.1333" iyz="0.0" izz="0.2667"/>
    </inertial>
  </link>

  <joint name="base_joint" type="fixed">
    <origin xyz="0.0 0.0 0.3" rpy="0.0 0.0 0.0"/>
    <parent link="base_footprint"/>
    <child link="base_link"/>
  </joint>

  
  <!-- Wheel Macro -->
  <xacro:macro name="wheel" params="name x y">
    <link name="wheel_${name}_link">
      <visual>
        <geometry>
          <cylinder radius="0.2" length="0.05"/>       
        </geometry>
        <material name="Black">
          <color rgba="0.0 0.0 0.0 1.0"/>
        </material>
      </visual>
      <collision>
        <geometry>
          <cylinder radius="0.2" length="0.05"/>       
        </geometry>
      </collision>
      <inertial>
        <mass value="0.55"/>
        <origin xyz="0.0 0.0 0.0" rpy="1.570796326795 0.0 0.0"/>
        <inertia ixx="0.01" ixy="0.0" ixz="0.0" iyy="0.01" iyz="0.0" izz="0.01"/>
      </inertial>
    </link>

    <joint name="wheel_${name}_joint" type="continuous">
      <origin xyz="${x} ${y} -0.05" rpy="1.570796326795 0.0 0.0"/>
      <parent link="base_link"/>
      <child link="wheel_${name}_link"/>
      <axis xyz="0.0 0.0 1.0"/>  
    </joint>
  </xacro:macro>

  <!-- Wheels -->
  <xacro:wheel name="front_right" x="0.3" y="0.45"/>
  <xacro:wheel name="rear_right" x="-0.3" y="0.45"/>
  <xacro:wheel name="rear_left" x="-0.3" y="-0.45"/>
  <xacro:wheel name="front_left" x="0.3" y="-0.45"/>
</robot>